Workbook
Name DossierPDF: IF(LEFT(CELL("filename",Références!$A$1),9)="C:\Users\",LEFT(CELL("filename",Références!$A$1),FIND("\",CELL("filename",Références!$A$1),10))&"OneDrive - entpe.fr\bibliographie\","")

Sheet Lisez-moi
B2: Bibliographie de thèse — Lucas DAVID
B3: Distribution hétérogène de la pression de contact pneu-chaussée propagée dans un calcul EF viscoélastique — chaussées aéronautiques (ENTPE, LTDS, partenariat STAC). Vérification sur sources primaires du 22/09/2026.
B5: En chiffres (calculé)
B6: Références | C6: ='Tableau de bord'!C6&" références, dont "&'Tableau de bord'!C7&" issues de la bibliographie du TFE" -> 179 références, dont 39 issues de la bibliographie du TFE
B7: Vérification | C7: ='Tableau de bord'!C8&" vérifiées sur source primaire, "&'Tableau de bord'!C9&" partiellement, "&'Tableau de bord'!C10&" non vérifiée(s) ; "&'Tableau de bord'!C11&" DOI, tous résolus" -> 140 vérifiées sur source primaire, 38 partiellement, 1 non vérifiée(s) ; 106 DOI, tous résolus
B8: Accès | C8: ='Tableau de bord'!C12&" téléchargeables tout de suite, "&'Tableau de bord'!C13&" via l'abonnement ENTPE, "&'Tableau de bord'!C14&" payantes, "&'Tableau de bord'!C15&" à demander ou localiser" -> 56 téléchargeables tout de suite, 80 via l'abonnement ENTPE, 28 payantes, 15 à demander ou localiser
B9: Où tu en es | C9: ='Tableau de bord'!C27&" : "&'Tableau de bord'!C17&" lues, "&'Tableau de bord'!C20&" en retard. Prochaine action : "&'Tableau de bord'!C32 -> 1 — octobre 2026 : 0 lues, 0 en retard. Prochaine action : Envoyer ou relancer 3 demande(s) : feuille Demandes
B10: Fiches de lecture | C10: =COUNTIF('Lecture détaillée'!$J$5:$J$204,"Complet")&" d'après un résumé complet, "&COUNTIF('Lecture détaillée'!$J$5:$J$204,"Partiel")&" d'après un texte partiel, "&COUNTIF('Lecture détaillée'!$J$5:$J$204,"Aucun")&" fiches de repérage (pas de résumé en ligne)" -> 70 d'après un résumé complet, 18 d'après un texte partiel, 91 fiches de repérage (pas de résumé en ligne)
B12: Nouveau : lecture détaillée et analyse croisée
B13: • Lecture détaillée : une fiche par référence (objectif, méthode, résultats annoncés, limites, ce que ça t'apporte, ce qu'il faudra vérifier en lisant), avec sept dimensions (pneu, contact, loi, méthode, chargement, cible, validation). Filtre par axe, par « Texte lu » ou par mot.
B14: • Les fiches viennent des résumés publiés, pas du texte intégral : 70 résumés complets, 18 textes partiels, 34 fiches de repérage pour les documents sans résumé en ligne (normes, ouvrages, thèses anciennes, manuels, rapport confidentiel du CSIR). Rien n'y est inventé : quand le résumé ne dit rien, la fiche le dit.
B15: • Analyse croisée : répartition par axe, croisements clés, synthèses par thème, convergences, divergences, lacunes, place de ta thèse et points à vérifier dans ton TFE. Matrice croisée : le classement de chaque référence, modifiable.
B16: • En relisant les résumés, une vingtaine de notes de la base ont été corrigées (par exemple : pas de nappe Tekscan dans les résumés de Manyo et d'Oubahdou ; piste 14R/32L de Toulouse = chaussée rigide renforcée ; pneu de tourisme chez He et al. 2021). Une correction s'ajoute à la feuille Corrections TFE.
B18: Ce qui change par rapport à la version précédente (63 références)
B19: • 122 références au lieu de 63, dont les 39 de la bibliographie du TFE, toutes revérifiées une par une ; les axes 3 (viscoélasticité), 4 (module complexe), 5 (calcul de structures) et 6 (endommagement) sont maintenant couverts.
B20: • Jiang et al. (2019) : le DOI cité dans le TFE ne mène nulle part ; le bon DOI est 10.1080/10298436.2017.1380803.
B21: • Rapport HTPT d'Airbus : il est public (site d'Airbus) ; sa Figure 26 montre des pressions calculées, pas mesurées (légende de ta Figure 1-23 à corriger).
B22: • Normes : NF EN 1427 citée dans l'édition de janvier 2018, annulée en juin 2026 ; module complexe = NF EN 12697-26+A1 (2023) ; NF EN 1426, citée dans ton texte, est ajoutée.
B23: • OACI : Annexe 14 vol. I, 9e édition (2022) ; Doc 9157 partie 3, 3e édition (2022). Transition ACN-PCN vers ACR-PCR : adoptée en juillet 2020, applicable au 28/11/2024.
B24: • Les deux pistes de ta soutenance ont leurs références : domaine fréquentiel (VEROAD, Siddharthan, ViscoRoute, éléments spectraux) et superposition semi-analytique (Boussinesq, Love, Johnson, DC-FFT, code de Jacq, Manyo, Cardoso da Silva).
... B27: Les feuilles
B28: Tableau de bord | C28: Vue d'ensemble, avancement par axe et par mois, charge de lecture du mois, prochaines lectures conseillées, graphiques. Rien à saisir.
B29: Références | C29: La base : une ligne par référence. Colonnes jaunes à remplir (statut, date, PDF, Zotero, note, pertinence, commentaire). Colonne Ouvrir = lien le plus direct (PDF libre, sinon page éditeur par le DOI, sinon notice, sinon recherche). Groupes de colonnes repliables avec les boutons + / − au-dessus des en-têtes.
B30: Lecture détaillée | C30: Une fiche de lecture par référence, d'après son résumé, liée par l'ID ; colonne « Texte lu » : Complet, Partiel ou Aucun.
B31: Analyse croisée | C31: Répartition par axe et par catégorie (calculée), croisements clés, synthèses par thème, convergences, divergences, lacunes, place de ta thèse, points à vérifier dans le TFE.
B32: Matrice croisée | C32: Le classement de chaque référence (● par catégorie) ; les totaux et l'Analyse croisée en dépendent. Modifiable.
B33: Planning | C33: Six mois, octobre 2026 → mars 2027 : objectif de fin de mois, documents à demander en amont, liste des lectures tirée de Références.
B34: Demandes | C34: PEB, documentation ENTPE, STAC : date limite d'envoi calculée d'après le délai, relance automatique à +21 jours (réglable).
B35: Corrections TFE | C35: Les écarts constatés entre ta bibliographie de TFE et les sources primaires, avec la correction et sa source.
B36: Pistes non couvertes | C36: Sujets cherchés sans source vérifiable. Rien n'y est inventé.
B37: Notes de lecture | C37: Une ligne par référence, liée par l'ID (le tri de Références ne casse rien).
B38: Paramètres | C38: Date de début, capacité mensuelle, barème du score, temps de lecture par priorité, dossiers utilisés par les macros, listes de choix.
B40: Couleurs
B41: Fond jaune | C41: Cellule à remplir ou réglage modifiable.
B42: Fond gris | C42: Cellule calculée : ne pas écrire dedans.
B43: Rouge / orange / vert | C43: En retard, non vérifié ou à demander / ce mois-ci, partiel ou payant / lu, vérifié ou PDF libre.
B45: Exemple de ligne de notes remplie
B46: ID | C46: BIB-0xx (Tiouajni et al. 2011)
B47: Apport central (reformulé) | C47: Approche un modèle à spectre continu (2S2P1D) par un Kelvin-Voigt généralisé de taille finie, en 3D, en ajustant les modules sur une grille de temps de retard.
B48: Lien avec mes travaux | C48: Méthode suivie pour mes 9 branches (§2.7) ; vérifier la plage de fréquences et le nombre de branches retenus.
...

Sheet Tableau de bord
B2: Tableau de bord bibliographique
B3: Tout est calculé depuis la feuille Références : rien à saisir ici.
B4: Vue d'ensemble | F4: Avancement par axe
B5: Indicateur | C5: Valeur | F5: Axe | G5: Intitulé | H5: Total | I5: INCONTOURNABLE | J5: Lues | K5: Reste | L5: % lu | M5: Heures restantes
B6: Références au total | C6: =COUNTA(Références!$B$2:$B$201) -> 179 | F6: 1 | G6: Mesure de la pression de contact pneu-chaussée | H6: =COUNTIF(Références!$G$2:$G$201,F6) -> 16 | I6: =COUNTIFS(Références!$G$2:$G$201,F6,Références!$H$2:$H$201,"INCONTOURNABLE") -> 3 | J6: =COUNTIFS(Références!$G$2:$G$201,F6,Références!$J$2:$J$201,"Lu") -> 0 | K6: =H6-J6-COUNTIFS(Références!$G$2:$G$201,F6,Références!$J$2:$J$201,"Écarté") -> 16 | L6: =IFERROR(J6/(H6-COUNTIFS(Références!$G$2:$G$201,F6,Références!$J$2:$J$201,"Écarté")),0) -> 0 | M6: =SUMIFS(Références!$AT$2:$AT$201,Références!$G$2:$G$201,F6)-SUMIFS(Références!$AT$2:$AT$201,Références!$G$2:$G$201,F6,Références!$J$2:$J$201,"Lu")-SUMIFS(Références!$AT$2:$AT$201,Références!$G$2:$G$201,F6,Références!$J$2:$J$201,"Écarté") -> 45
B7: dont bibliographie du TFE | C7: =COUNTIF(Références!$F$2:$F$201,"Oui") -> 39 | F7: 2 | G7: Modélisation du pneu et du contact | H7: =COUNTIF(Références!$G$2:$G$201,F7) -> 36 | I7: =COUNTIFS(Références!$G$2:$G$201,F7,Références!$H$2:$H$201,"INCONTOURNABLE") -> 4 | J7: =COUNTIFS(Références!$G$2:$G$201,F7,Références!$J$2:$J$201,"Lu") -> 0 | K7: =H7-J7-COUNTIFS(Références!$G$2:$G$201,F7,Références!$J$2:$J$201,"Écarté") -> 36 | L7: =IFERROR(J7/(H7-COUNTIFS(Références!$G$2:$G$201,F7,Références!$J$2:$J$201,"Écarté")),0) -> 0 | M7: =SUMIFS(Références!$AT$2:$AT$201,Références!$G$2:$G$201,F7)-SUMIFS(Références!$AT$2:$AT$201,Références!$G$2:$G$201,F7,Références!$J$2:$J$201,"Lu")-SUMIFS(Références!$AT$2:$AT$201,Références!$G$2:$G$201,F7,Références!$J$2:$J$201,"Écarté") -> 80
B8: Vérifiées sur source primaire | C8: =COUNTIF(Références!$AL$2:$AL$201,"Vérifié") -> 140 | F8: 3 | G8: Viscoélasticité des enrobés | H8: =COUNTIF(Références!$G$2:$G$201,F8) -> 20 | I8: =COUNTIFS(Références!$G$2:$G$201,F8,Références!$H$2:$H$201,"INCONTOURNABLE") -> 3 | J8: =COUNTIFS(Références!$G$2:$G$201,F8,Références!$J$2:$J$201,"Lu") -> 0 | K8: =H8-J8-COUNTIFS(Références!$G$2:$G$201,F8,Références!$J$2:$J$201,"Écarté") -> 20 | L8: =IFERROR(J8/(H8-COUNTIFS(Références!$G$2:$G$201,F8,Références!$J$2:$J$201,"Écarté")),0) -> 0 | M8: =SUMIFS(Références!$AT$2:$AT$201,Références!$G$2:$G$201,F8)-SUMIFS(Références!$AT$2:$AT$201,Références!$G$2:$G$201,F8,Références!$J$2:$J$201,"Lu")-SUMIFS(Références!$AT$2:$AT$201,Références!$G$2:$G$201,F8,Références!$J$2:$J$201,"Écarté") -> 57
B9: Vérification partielle | C9: =COUNTIF(Références!$AL$2:$AL$201,"Partiel") -> 38 | F9: 4 | G9: Caractérisation expérimentale du module complexe | H9: =COUNTIF(Références!$G$2:$G$201,F9) -> 10 | I9: =COUNTIFS(Références!$G$2:$G$201,F9,Références!$H$2:$H$201,"INCONTOURNABLE") -> 3 | J9: =COUNTIFS(Références!$G$2:$G$201,F9,Références!$J$2:$J$201,"Lu") -> 0 | K9: =H9-J9-COUNTIFS(Références!$G$2:$G$201,F9,Références!$J$2:$J$201,"Écarté") -> 10 | L9: =IFERROR(J9/(H9-COUNTIFS(Références!$G$2:$G$201,F9,Références!$J$2:$J$201,"Écarté")),0) -> 0 | M9: =SUMIFS(Références!$AT$2:$AT$201,Références!$G$2:$G$201,F9)-SUMIFS(Références!$AT$2:$AT$201,Références!$G$2:$G$201,F9,Références!$J$2:$J$201,"Lu")-SUMIFS(Références!$AT$2:$AT$201,Références!$G$2:$G$201,F9,Références!$J$2:$J$201,"Écarté") -> 31
B10: Non vérifiées | C10: =COUNTIF(Références!$AL$2:$AL$201,"Non vérifié") -> 1 | F10: 5 | G10: Calcul de structures viscoélastiques | H10: =COUNTIF(Références!$G$2:$G$201,F10) -> 45 | I10: =COUNTIFS(Références!$G$2:$G$201,F10,Références!$H$2:$H$201,"INCONTOURNABLE") -> 6 | J10: =COUNTIFS(Références!$G$2:$G$201,F10,Références!$J$2:$J$201,"Lu") -> 0 | K10: =H10-J10-COUNTIFS(Références!$G$2:$G$201,F10,Références!$J$2:$J$201,"Écarté") -> 45 | L10: =IFERROR(J10/(H10-COUNTIFS(Références!$G$2:$G$201,F10,Références!$J$2:$J$201,"Écarté")),0) -> 0 | M10: =SUMIFS(Références!$AT$2:$AT$201,Références!$G$2:$G$201,F10)-SUMIFS(Références!$AT$2:$AT$201,Références!$G$2:$G$201,F10,Références!$J$2:$J$201,"Lu")-SUMIFS(Références!$AT$2:$AT$201,Références!$G$2:$G$201,F10,Références!$J$2:$J$201,"Écarté") -> 123
B11: Avec DOI vérifié | C11: =COUNTA(Références!$AC$2:$AC$201) -> 106 | F11: 6 | G11: Fatigue et endommagement | H11: =COUNTIF(Références!$G$2:$G$201,F11) -> 23 | I11: =COUNTIFS(Références!$G$2:$G$201,F11,Références!$H$2:$H$201,"INCONTOURNABLE") -> 4 | J11: =COUNTIFS(Références!$G$2:$G$201,F11,Références!$J$2:$J$201,"Lu") -> 0 | K11: =H11-J11-COUNTIFS(Références!$G$2:$G$201,F11,Références!$J$2:$J$201,"Écarté") -> 23 | L11: =IFERROR(J11/(H11-COUNTIFS(Références!$G$2:$G$201,F11,Références!$J$2:$J$201,"Écarté")),0) -> 0 | M11: =SUMIFS(Références!$AT$2:$AT$201,Références!$G$2:$G$201,F11)-SUMIFS(Références!$AT$2:$AT$201,Références!$G$2:$G$201,F11,Références!$J$2:$J$201,"Lu")-SUMIFS(Références!$AT$2:$AT$201,Références!$G$2:$G$201,F11,Références!$J$2:$J$201,"Écarté") -> 65
B12: Téléchargeables tout de suite (PDF libre) | C12: =COUNTIF(Références!$AJ$2:$AJ$201,"PDF libre")+COUNTIF(Références!$AJ$2:$AJ$201,"PDF libre (dépôt)") -> 56 | F12: 7 | G12: Chaussées aéronautiques | H12: =COUNTIF(Références!$G$2:$G$201,F12) -> 22 | I12: =COUNTIFS(Références!$G$2:$G$201,F12,Références!$H$2:$H$201,"INCONTOURNABLE") -> 5 | J12: =COUNTIFS(Références!$G$2:$G$201,F12,Références!$J$2:$J$201,"Lu") -> 0 | K12: =H12-J12-COUNTIFS(Références!$G$2:$G$201,F12,Références!$J$2:$J$201,"Écarté") -> 22 | L12: =IFERROR(J12/(H12-COUNTIFS(Références!$G$2:$G$201,F12,Références!$J$2:$J$201,"Écarté")),0) -> 0 | M12: =SUMIFS(Références!$AT$2:$AT$201,Références!$G$2:$G$201,F12)-SUMIFS(Références!$AT$2:$AT$201,Références!$G$2:$G$201,F12,Références!$J$2:$J$201,"Lu")-SUMIFS(Références!$AT$2:$AT$201,Références!$G$2:$G$201,F12,Références!$J$2:$J$201,"Écarté") -> 73
B13: Via l'abonnement de l'ENTPE (éditeur) | C13: =COUNTIF(Références!$AJ$2:$AJ$201,"Éditeur (abonnement)") -> 80 | F13: 8 | G13: Littérature grise et normative | H13: =COUNTIF(Références!$G$2:$G$201,F13) -> 7 | I13: =COUNTIFS(Références!$G$2:$G$201,F13,Références!$H$2:$H$201,"INCONTOURNABLE") -> 0 | J13: =COUNTIFS(Références!$G$2:$G$201,F13,Références!$J$2:$J$201,"Lu") -> 0 | K13: =H13-J13-COUNTIFS(Références!$G$2:$G$201,F13,Références!$J$2:$J$201,"Écarté") -> 7 | L13: =IFERROR(J13/(H13-COUNTIFS(Références!$G$2:$G$201,F13,Références!$J$2:$J$201,"Écarté")),0) -> 0 | M13: =SUMIFS(Références!$AT$2:$AT$201,Références!$G$2:$G$201,F13)-SUMIFS(Références!$AT$2:$AT$201,Références!$G$2:$G$201,F13,Références!$J$2:$J$201,"Lu")-SUMIFS(Références!$AT$2:$AT$201,Références!$G$2:$G$201,F13,Références!$J$2:$J$201,"Écarté") -> 11
B14: Payantes (normes, OACI, SAE, RGRA) | C14: =COUNTIF(Références!$AJ$2:$AJ$201,"Payant (boutique)") -> 28 | F14: Total | H14: =SUM(H6:H13) -> 179 | I14: =SUM(I6:I13) -> 28 | J14: =SUM(J6:J13) -> 0 | K14: =SUM(K6:K13) -> 179 | M14: =SUM(M6:M13) -> 485
B15: À demander ou à localiser | C15: =COUNTIF(Références!$AJ$2:$AJ$201,"Non diffusé (à demander)")+COUNTIF(Références!$AJ$2:$AJ$201,"Notice en ligne (texte à localiser)") -> 15 | F15: Avancement par mois
B16: Lecture | F16: Mois | G16: Libellé | H16: Total | I16: Lues | J16: Reste | K16: Heures prévues | L16: Heures restantes | M16: Capacité | N16: Charge | O16: État
B17: Lues | C17: =COUNTIF(Références!$J$2:$J$201,"Lu") -> 0 | F17: 1 | G17: octobre 2026 | H17: =COUNTIF(Références!$I$2:$I$201,F17) -> 20 | I17: =COUNTIFS(Références!$I$2:$I$201,F17,Références!$J$2:$J$201,"Lu") -> 0 | J17: =H17-I17-COUNTIFS(Références!$I$2:$I$201,F17,Références!$J$2:$J$201,"Écarté") -> 20 | K17: =SUMIFS(Références!$AT$2:$AT$201,Références!$I$2:$I$201,F17) -> 72 | L17: =K17-SUMIFS(Références!$AT$2:$AT$201,Références!$I$2:$I$201,F17,Références!$J$2:$J$201,"Lu")-SUMIFS(Références!$AT$2:$AT$201,Références!$I$2:$I$201,F17,Références!$J$2:$J$201,"Écarté") -> 72 | M17: =Paramètres!$C$10 -> 65 | N17: =IFERROR(K17/M17,0) -> 1.1076923 | O17: =IF(J17=0,"Terminé",IF(F17<Paramètres!$C$8,"En retard",IF(F17=Paramètres!$C$8,"En cours","À venir"))) -> En cours
B18: En cours de lecture | C18: =COUNTIF(Références!$J$2:$J$201,"En cours") -> 0 | F18: 2 | G18: novembre 2026 | H18: =COUNTIF(Références!$I$2:$I$201,F18) -> 29 | I18: =COUNTIFS(Références!$I$2:$I$201,F18,Références!$J$2:$J$201,"Lu") -> 0 | J18: =H18-I18-COUNTIFS(Références!$I$2:$I$201,F18,Références!$J$2:$J$201,"Écarté") -> 29 | K18: =SUMIFS(Références!$AT$2:$AT$201,Références!$I$2:$I$201,F18) -> 70 | L18: =K18-SUMIFS(Références!$AT$2:$AT$201,Références!$I$2:$I$201,F18,Références!$J$2:$J$201,"Lu")-SUMIFS(Références!$AT$2:$AT$201,Références!$I$2:$I$201,F18,Références!$J$2:$J$201,"Écarté") -> 70 | M18: =Paramètres!$C$10 -> 65 | N18: =IFERROR(K18/M18,0) -> 1.0769231 | O18: =IF(J18=0,"Terminé",IF(F18<Paramètres!$C$8,"En retard",IF(F18=Paramètres!$C$8,"En cours","À venir"))) -> À venir
B19: Taux de lecture | C19: =IFERROR(C17/(C6-COUNTIF(Références!$J$2:$J$201,"Écarté")),0) -> 0 | F19: 3 | G19: décembre 2026 | H19: =COUNTIF(Références!$I$2:$I$201,F19) -> 20 | I19: =COUNTIFS(Références!$I$2:$I$201,F19,Références!$J$2:$J$201,"Lu") -> 0 | J19: =H19-I19-COUNTIFS(Références!$I$2:$I$201,F19,Références!$J$2:$J$201,"Écarté") -> 20 | K19: =SUMIFS(Références!$AT$2:$AT$201,Références!$I$2:$I$201,F19) -> 55 | L19: =K19-SUMIFS(Références!$AT$2:$AT$201,Références!$I$2:$I$201,F19,Références!$J$2:$J$201,"Lu")-SUMIFS(Références!$AT$2:$AT$201,Références!$I$2:$I$201,F19,Références!$J$2:$J$201,"Écarté") -> 55 | M19: =Paramètres!$C$10 -> 65 | N19: =IFERROR(K19/M19,0) -> 0.84615385 | O19: =IF(J19=0,"Terminé",IF(F19<Paramètres!$C$8,"En retard",IF(F19=Paramètres!$C$8,"En cours","À venir"))) -> À venir
B20: En retard | C20: =COUNTIF(Références!$K$2:$K$201,"EN RETARD") -> 0 | F20: 4 | G20: janvier 2027 | H20: =COUNTIF(Références!$I$2:$I$201,F20) -> 29 | I20: =COUNTIFS(Références!$I$2:$I$201,F20,Références!$J$2:$J$201,"Lu") -> 0 | J20: =H20-I20-COUNTIFS(Références!$I$2:$I$201,F20,Références!$J$2:$J$201,"Écarté") -> 29 | K20: =SUMIFS(Références!$AT$2:$AT$201,Références!$I$2:$I$201,F20) -> 73 | L20: =K20-SUMIFS(Références!$AT$2:$AT$201,Références!$I$2:$I$201,F20,Références!$J$2:$J$201,"Lu")-SUMIFS(Références!$AT$2:$AT$201,Références!$I$2:$I$201,F20,Références!$J$2:$J$201,"Écarté") -> 73 | M20: =Paramètres!$C$10 -> 65 | N20: =IFERROR(K20/M20,0) -> 1.1230769 | O20: =IF(J20=0,"Terminé",IF(F20<Paramètres!$C$8,"En retard",IF(F20=Paramètres!$C$8,"En cours","À venir"))) -> À venir
B21: À lire ce mois-ci | C21: =COUNTIF(Références!$K$2:$K$201,"Ce mois-ci") -> 20 | F21: 5 | G21: février 2027 | H21: =COUNTIF(Références!$I$2:$I$201,F21) -> 41 | I21: =COUNTIFS(Références!$I$2:$I$201,F21,Références!$J$2:$J$201,"Lu") -> 0 | J21: =H21-I21-COUNTIFS(Références!$I$2:$I$201,F21,Références!$J$2:$J$201,"Écarté") -> 41 | K21: =SUMIFS(Références!$AT$2:$AT$201,Références!$I$2:$I$201,F21) -> 112 | L21: =K21-SUMIFS(Références!$AT$2:$AT$201,Références!$I$2:$I$201,F21,Références!$J$2:$J$201,"Lu")-SUMIFS(Références!$AT$2:$AT$201,Références!$I$2:$I$201,F21,Références!$J$2:$J$201,"Écarté") -> 112 | M21: =Paramètres!$C$10 -> 65 | N21: =IFERROR(K21/M21,0) -> 1.7230769 | O21: =IF(J21=0,"Terminé",IF(F21<Paramètres!$C$8,"En retard",IF(F21=Paramètres!$C$8,"En cours","À venir"))) -> À venir
B22: PDF libres encore à télécharger | C22: =COUNTIFS(Références!$AJ$2:$AJ$201,"PDF libre",Références!$O$2:$O$201,"<>Oui")+COUNTIFS(Références!$AJ$2:$AJ$201,"PDF libre (dépôt)",Références!$O$2:$O$201,"<>Oui") -> 29 | F22: 6 | G22: mars 2027 | H22: =COUNTIF(Références!$I$2:$I$201,F22) -> 40 | I22: =COUNTIFS(Références!$I$2:$I$201,F22,Références!$J$2:$J$201,"Lu") -> 0 | J22: =H22-I22-COUNTIFS(Références!$I$2:$I$201,F22,Références!$J$2:$J$201,"Écarté") -> 40 | K22: =SUMIFS(Références!$AT$2:$AT$201,Références!$I$2:$I$201,F22) -> 103 | L22: =K22-SUMIFS(Références!$AT$2:$AT$201,Références!$I$2:$I$201,F22,Références!$J$2:$J$201,"Lu")-SUMIFS(Références!$AT$2:$AT$201,Références!$I$2:$I$201,F22,Références!$J$2:$J$201,"Écarté") -> 103 | M22: =Paramètres!$C$10 -> 65 | N22: =IFERROR(K22/M22,0) -> 1.5846154 | O22: =IF(J22=0,"Terminé",IF(F22<Paramètres!$C$8,"En retard",IF(F22=Paramètres!$C$8,"En cours","À venir"))) -> À venir
B23: Demandes à envoyer ou à relancer | C23: =COUNTIF(Demandes!$N$4:$N$40,"ENVOYER MAINTENANT")+COUNTIF(Demandes!$N$4:$N$40,"RELANCER") -> 3 | F23: Total | H23: =SUM(H17:H22) -> 179 | I23: =SUM(I17:I22) -> 0 | J23: =SUM(J17:J22) -> 179 | K23: =SUM(K17:K22) -> 485 | L23: =SUM(L17:L22) -> 485
B24: Corrections du TFE restantes | C24: =COUNTIF('Corrections TFE'!$H$4:$H$60,"Non") -> 20
F25: Prochaines lectures conseillées (plus haut score, non lues)
B26: Ce mois-ci | F26: Rang | G26: Citation | H26: Priorité | I26: Mois | J26: Score | K26: Ouvrir | L26: Titre
B27: Mois du plan en cours | C27: =IF(Paramètres!$C$8>6,"Plan terminé",Paramètres!$C$8&" — "&INDEX(Paramètres!$T$6:$T$11,Paramètres!$C$8)) -> 1 — octobre 2026 | F27: 1 | G27: =IF(J27<1,"",INDEX(Références!$C$2:$C$201,MATCH(LARGE(Références!$BA$2:$BA$201,1),Références!$BA$2:$BA$201,0))) -> De Beer et al. (2012) | H27: =IF(J27<1,"",INDEX(Références!$H$2:$H$201,MATCH(LARGE(Références!$BA$2:$BA$201,1),Références!$BA$2:$BA$201,0))) -> INCONTOURNABLE | I27: =IF(J27<1,"",INDEX(Références!$I$2:$I$201,MATCH(LARGE(Références!$BA$2:$BA$201,1),Références!$BA$2:$BA$201,0))) -> 1 | J27: =IFERROR(LARGE(Références!$BA$2:$BA$201,1),0) -> 140.00998 | K27: =IF(J27<1,"",HYPERLINK(INDEX(Références!$AF$2:$AF$201,MATCH(LARGE(Références!$BA$2:$BA$201,1),Références!$BA$2:$BA$201,0)),"Ouvrir")) -> Ouvrir | L27: =IF(J27<1,"",INDEX(Références!$D$2:$D$201,MATCH(LARGE(Références!$BA$2:$BA$201,1),Références!$BA$2:$BA$201,0))) -> Toward using tire-road contact stresses in pavement design and analysis
B28: Heures restantes ce mois-ci | C28: =SUMIFS(Références!$AT$2:$AT$201,Références!$I$2:$I$201,Paramètres!$C$8)-SUMIFS(Références!$AT$2:$AT$201,Références!$I$2:$I$201,Paramètres!$C$8,Références!$J$2:$J$201,"Lu")-SUMIFS(Références!$AT$2:$AT$201,Références!$I$2:$I$201,Paramètres!$C$8,Références!$J$2:$J$201,"Écarté") -> 72 | F28: 2 | G28: =IF(J28<1,"",INDEX(Références!$C$2:$C$201,MATCH(LARGE(Références!$BA$2:$BA$201,2),Références!$BA$2:$BA$201,0))) -> Sadoun et al. (2022) | H28: =IF(J28<1,"",INDEX(Références!$H$2:$H$201,MATCH(LARGE(Références!$BA$2:$BA$201,2),Références!$BA$2:$BA$201,0))) -> INCONTOURNABLE | I28: =IF(J28<1,"",INDEX(Références!$I$2:$I$201,MATCH(LARGE(Références!$BA$2:$BA$201,2),Références!$BA$2:$BA$201,0))) -> 1 | J28: =IFERROR(LARGE(Références!$BA$2:$BA$201,2),0) -> 140.00995 | K28: =IF(J28<1,"",HYPERLINK(INDEX(Références!$AF$2:$AF$201,MATCH(LARGE(Références!$BA$2:$BA$201,2),Références!$BA$2:$BA$201,0)),"Ouvrir")) -> Ouvrir | L28: =IF(J28<1,"",INDEX(Références!$D$2:$D$201,MATCH(LARGE(Références!$BA$2:$BA$201,2),Références!$BA$2:$BA$201,0))) -> Top-down cracking in airfield pavement structures—An in-situ test survey
B29: Heures en retard (mois passés) | C29: =SUMIFS(Références!$AT$2:$AT$201,Références!$K$2:$K$201,"EN RETARD") -> 0 | F29: 3 | G29: =IF(J29<1,"",INDEX(Références!$C$2:$C$201,MATCH(LARGE(Références!$BA$2:$BA$201,3),Références!$BA$2:$BA$201,0))) -> Airbus S.A.S. (2010) | H29: =IF(J29<1,"",INDEX(Références!$H$2:$H$201,MATCH(LARGE(Références!$BA$2:$BA$201,3),Références!$BA$2:$BA$201,0))) -> INCONTOURNABLE | I29: =IF(J29<1,"",INDEX(Références!$I$2:$I$201,MATCH(LARGE(Références!$BA$2:$BA$201,3),Références!$BA$2:$BA$201,0))) -> 1 | J29: =IFERROR(LARGE(Références!$BA$2:$BA$201,3),0) -> 140.00994 | K29: =IF(J29<1,"",HYPERLINK(INDEX(Références!$AF$2:$AF$201,MATCH(LARGE(Références!$BA$2:$BA$201,3),Références!$BA$2:$BA$201,0)),"Ouvrir")) -> Ouvrir | L29: =IF(J29<1,"",INDEX(Références!$D$2:$D$201,MATCH(LARGE(Références!$BA$2:$BA$201,3),Références!$BA$2:$BA$201,0))) -> High Tire Pressure Test (HTPT) — Final report
B30: Capacité mensuelle (h) | C30: =Paramètres!$C$10 -> 65 | F30: 4 | G30: =IF(J30<1,"",INDEX(Références!$C$2:$C$201,MATCH(LARGE(Références!$BA$2:$BA$201,4),Références!$BA$2:$BA$201,0))) -> Petitjean et al. (2001) | H30: =IF(J30<1,"",INDEX(Références!$H$2:$H$201,MATCH(LARGE(Références!$BA$2:$BA$201,4),Références!$BA$2:$BA$201,0))) -> INCONTOURNABLE | I30: =IF(J30<1,"",INDEX(Références!$I$2:$I$201,MATCH(LARGE(Références!$BA$2:$BA$201,4),Références!$BA$2:$BA$201,0))) -> 1 | J30: =IFERROR(LARGE(Références!$BA$2:$BA$201,4),0) -> 140.00993 | K30: =IF(J30<1,"",HYPERLINK(INDEX(Références!$AF$2:$AF$201,MATCH(LARGE(Références!$BA$2:$BA$201,4),Références!$BA$2:$BA$201,0)),"Ouvrir")) -> Ouvrir | L30: =IF(J30<1,"",INDEX(Références!$D$2:$D$201,MATCH(LARGE(Références!$BA$2:$BA$201,4),Références!$BA$2:$BA$201,0))) -> LCPC / Airbus / STBA A380 Pavement Experimental Programme
B31: Charge | C31: =IF(C28+C29>C30,"Surcharge : reporter des « A consulter » au mois suivant","Dans la capacité") -> Surcharge : reporter des « A consulter » au mois suivant | F31: 5 | G31: =IF(J31<1,"",INDEX(Références!$C$2:$C$201,MATCH(LARGE(Références!$BA$2:$BA$201,5),Références!$BA$2:$BA$201,0))) -> Olard & Di Benedetto (2003) | H31: =IF(J31<1,"",INDEX(Références!$H$2:$H$201,MATCH(LARGE(Références!$BA$2:$BA$201,5),Références!$BA$2:$BA$201,0))) -> INCONTOURNABLE | I31: =IF(J31<1,"",INDEX(Références!$I$2:$I$201,MATCH(LARGE(Références!$BA$2:$BA$201,5),Références!$BA$2:$BA$201,0))) -> 2 | J31: =IFERROR(LARGE(Références!$BA$2:$BA$201,5),0) -> 135.00979 | K31: =IF(J31<1,"",HYPERLINK(INDEX(Références!$AF$2:$AF$201,MATCH(LARGE(Références!$BA$2:$BA$201,5),Références!$BA$2:$BA$201,0)),"Ouvrir")) -> Ouvrir | L31: =IF(J31<1,"",INDEX(Références!$D$2:$D$201,MATCH(LARGE(Références!$BA$2:$BA$201,5),Références!$BA$2:$BA$201,0))) -> General "2S2P1D" model and relation between the linear viscoelastic behaviours of bituminous binders and mixes
B32: Prochaine action | C32: =IF(C23>0,"Envoyer ou relancer "&C23&" demande(s) : feuille Demandes",IF(C22>0,"Télécharger "&C22&" PDF libre(s) : colonne Ouvrir",IF(G27="","Rien en attente","Lire "&G27))) -> Envoyer ou relancer 3 demande(s) : feuille Demandes | F32: 6 | G32: =IF(J32<1,"",INDEX(Références!$C$2:$C$201,MATCH(LARGE(Références!$BA$2:$BA$201,6),Références!$BA$2:$BA$201,0))) -> Tiouajni et al. (2011) | H32: =IF(J32<1,"",INDEX(Références!$H$2:$H$201,MATCH(LARGE(Références!$BA$2:$BA$201,6),Références!$BA$2:$BA$201,0))) -> INCONTOURNABLE | I32: =IF(J32<1,"",INDEX(Références!$I$2:$I$201,MATCH(LARGE(Références!$BA$2:$BA$201,6),Références!$BA$2:$BA$201,0))) -> 2 | J32: =IFERROR(LARGE(Références!$BA$2:$BA$201,6),0) -> 135.00978 | K32: =IF(J32<1,"",HYPERLINK(INDEX(Références!$AF$2:$AF$201,MATCH(LARGE(Références!$BA$2:$BA$201,6),Références!$BA$2:$BA$201,0)),"Ouvrir")) -> Ouvrir | L32: =IF(J32<1,"",INDEX(Références!$D$2:$D$201,MATCH(LARGE(Références!$BA$2:$BA$201,6),Références!$BA$2:$BA$201,0))) -> Approximation of linear viscoelastic model in the 3 dimensional case with mechanical analogues of finite size: Application to bituminous materials
F33: 7 | G33: =IF(J33<1,"",INDEX(Références!$C$2:$C$201,MATCH(LARGE(Références!$BA$2:$BA$201,7),Références!$BA$2:$BA$201,0))) -> De Beer & Fisher (2013) | H33: =IF(J33<1,"",INDEX(Références!$H$2:$H$201,MATCH(LARGE(Références!$BA$2:$BA$201,7),Références!$BA$2:$BA$201,0))) -> INCONTOURNABLE | I33: =IF(J33<1,"",INDEX(Références!$I$2:$I$201,MATCH(LARGE(Références!$BA$2:$BA$201,7),Références!$BA$2:$BA$201,0))) -> 1 | J33: =IFERROR(LARGE(Références!$BA$2:$BA$201,7),0) -> 130.00997 | K33: =IF(J33<1,"",HYPERLINK(INDEX(Références!$AF$2:$AF$201,MATCH(LARGE(Références!$BA$2:$BA$201,7),Références!$BA$2:$BA$201,0)),"Ouvrir")) -> Ouvrir | L33: =IF(J33<1,"",INDEX(Références!$D$2:$D$201,MATCH(LARGE(Références!$BA$2:$BA$201,7),Références!$BA$2:$BA$201,0))) -> Stress-In-Motion (SIM) system for capturing tri-axial tyre–road interaction in the contact patch
F34: 8 | G34: =IF(J34<1,"",INDEX(Références!$C$2:$C$201,MATCH(LARGE(Références!$BA$2:$BA$201,8),Références!$BA$2:$BA$201,0))) -> Tielking (1989) | H34: =IF(J34<1,"",INDEX(Références!$H$2:$H$201,MATCH(LARGE(Références!$BA$2:$BA$201,8),Références!$BA$2:$BA$201,0))) -> INCONTOURNABLE | I34: =IF(J34<1,"",INDEX(Références!$I$2:$I$201,MATCH(LARGE(Références!$BA$2:$BA$201,8),Références!$BA$2:$BA$201,0))) -> 1 | J34: =IFERROR(LARGE(Références!$BA$2:$BA$201,8),0) -> 130.00996 | K34: =IF(J34<1,"",HYPERLINK(INDEX(Références!$AF$2:$AF$201,MATCH(LARGE(Références!$BA$2:$BA$201,8),Références!$BA$2:$BA$201,0)),"Ouvrir")) -> Ouvrir | L34: =IF(J34<1,"",INDEX(Références!$D$2:$D$201,MATCH(LARGE(Références!$BA$2:$BA$201,8),Références!$BA$2:$BA$201,0))) -> Aircraft tire/pavement pressure distribution
F36: Accès aux documents
G37: Accès document | H37: Nombre | I37: Part
G38: PDF libre | H38: =COUNTIF(Références!$AJ$2:$AJ$201,G38) -> 41 | I38: =IFERROR(H38/$C$6,0) -> 0.22905028
G39: PDF libre (dépôt) | H39: =COUNTIF(Références!$AJ$2:$AJ$201,G39) -> 15 | I39: =IFERROR(H39/$C$6,0) -> 0.083798883
G40: Éditeur (abonnement) | H40: =COUNTIF(Références!$AJ$2:$AJ$201,G40) -> 80 | I40: =IFERROR(H40/$C$6,0) -> 0.44692737
G41: Payant (boutique) | H41: =COUNTIF(Références!$AJ$2:$AJ$201,G41) -> 28 | I41: =IFERROR(H41/$C$6,0) -> 0.15642458
G42: Non diffusé (à demander) | H42: =COUNTIF(Références!$AJ$2:$AJ$201,G42) -> 7 | I42: =IFERROR(H42/$C$6,0) -> 0.039106145
...

Sheet Références
A1: ID | B1: Clé | C1: Citation | D1: Titre | E1: Ouvrir | F1: TFE | G1: Axe | H1: Priorité | I1: Mois | J1: Statut lecture | K1: État | L1: Alerte | M1: Score | N1: Date lecture | O1: PDF récupéré | P1: Dans Zotero | Q1: Note Obsidian | R1: Pertinence (1-5) | S1: Commentaire | T1: Type RIS | U1: Type | V1: Auteurs | W1: Année | X1: Support (revue, actes) | Y1: Vol. | Z1: N° | AA1: Pages | AB1: Éditeur / institution | AC1: DOI | AD1: Identifiant (rapport, norme, ISBN, NNT, HAL) | AE1: Type de lien | AF1: Lien (URL) | AG1: doi.org | AH1: Chercher | AI1: Accès | AJ1: Accès document | AK1: Comment l'obtenir | AL1: Vérification | AM1: Source de vérification | AN1: Vérifié le | AO1: Contribution et lien avec tes travaux | AP1: Voir aussi | AQ1: Littérature grise | AR1: Intitulé de l'axe | AS1: Mois (libellé) | AT1: Temps estimé (h) | AU1: État du lien (macro) | AV1: Lien contrôlé le | AW1: Fichier de note | AX1: Rang dans le mois | AY1: Clé mois-rang | AZ1: URL de recherche | BA1: Score de tri | BB1: Fichier PDF
A2: BIB-001 | B2: debeer2012toward | C2: =IF($B2="","",IFERROR(LEFT(LEFT($V2,FIND(";",$V2&";")-1),FIND(",",LEFT($V2,FIND(";",$V2&";")-1))-1),LEFT($V2,FIND(";",$V2&";")-1))&IF((LEN($V2)-LEN(SUBSTITUTE($V2,";",""))+1)=1,"",IF((LEN($V2)-LEN(SUBSTITUTE($V2,";",""))+1)=2," & "&IFERROR(LEFT(TRIM(MID($V2,FIND(";",$V2)+1,FIND(";",$V2&";",FIND(";",$V2)+1)-FIND(";",$V2)-1)),FIND(",",TRIM(MID($V2,FIND(";",$V2)+1,FIND(";",$V2&";",FIND(";",$V2)+1)-FIND(";",$V2)-1)))-1),TRIM(MID($V2,FIND(";",$V2)+1,FIND(";",$V2&";",FIND(";",$V2)+1)-FIND(";",$V2)-1)))," et al."))&" ("&$W2&")") -> De Beer et al. (2012) | D2: Toward using tire-road contact stresses in pavement design and analysis | E2: =IF(OR($B2="",$AF2=""),"",HYPERLINK(IF(AND(Paramètres!$C$13<>"",$AJ2="Éditeur (abonnement)"),Paramètres!$C$13&$AF2,$AF2),"Ouvrir : "&$AE2)) -> Ouvrir : Page éditeur (DOI) | F2: Oui | G2: 1 | H2: INCONTOURNABLE | I2: 1 | J2: À lire | K2: =IF($B2="","",IF($J2="Lu","Lu",IF($J2="Écarté","Écarté",IF($I2<Paramètres!$C$8,"EN RETARD",IF($I2=Paramètres!$C$8,"Ce mois-ci",IF($I2=Paramètres!$C$8+1,"Mois prochain","À venir")))))) -> Ce mois-ci | L2: =IF($B2="","",IF($AL2="Non vérifié","Ne pas citer en l'état : métadonnées non vérifiées",IF($AL2="Partiel","Vérification à compléter avant de citer",IF($O2="Oui","",IF(OR($AJ2="PDF libre",$AJ2="PDF libre (dépôt)"),"PDF libre à télécharger",IF($AJ2="Éditeur (abonnement)","À télécharger via l'accès ENTPE",IF($AJ2="Payant (boutique)","À consulter via l'abonnement de l'école",IF($AJ2="Non diffusé (à demander)","Document à demander (feuille Demandes)","Texte intégral à localiser")))))))) | M2: =IF($B2="","",IF(OR($J2="Lu",$J2="Écarté"),0,IFERROR(INDEX(Paramètres!$C$17:$C$19,MATCH($H2,Paramètres!$B$17:$B$19,0)),0)+Paramètres!$C$20*(7-$I2)+IF($I2<Paramètres!$C$8,Paramètres!$C$21,0)+IF($F2="Oui",Paramètres!$C$22,0)+IF($AL2<>"Vérifié",Paramètres!$C$23,0)+IF(AND($O2<>"Oui",OR($AJ2="PDF libre",$AJ2="PDF libre (dépôt)")),Paramètres!$C$24,0))) -> 140 | O2: =IF($BB2="","Non",HYPERLINK(DossierPDF&$BB2,"Oui")) -> Oui | P2: Non | Q2: Non | T2: JOUR | U2: =IF($B2="","",IFERROR(INDEX(Paramètres!$N$6:$N$13,MATCH($T2,Paramètres!$M$6:$M$13,0)),$T2)) -> Article de revue | V2: De Beer, M.; Maina, J. W.; van Rensburg, Y.; Greben, J. M. | W2: 2012 | X2: Tire Science and Technology | Y2: 40 | Z2: 4 | AA2: 246-271 | AC2: 10.2346/tire.12.400403 | AE2: Page éditeur (DOI) | AF2: https://doi.org/10.2346/tire.12.400403 | AG2: =IF($AC2="","",HYPERLINK("https://doi.org/"&$AC2,"doi.org")) -> doi.org | AH2: =IF($AZ2="","",HYPERLINK($AZ2,"Scholar")) -> Scholar | AI2: Payant | AJ2: Éditeur (abonnement) | AK2: Tire Science and Technology (The Tire Society) : accès par abonnement ; résumé libre sur le dépôt du CSIR. | AL2: Vérifié | AM2: OpenAlex (DOI) + résumé CSIR | AN2: 22/09/2026 | AO2: Plaide pour intégrer des contraintes de contact mesurées dans le calcul des chaussées, en particulier près de la surface, où le modèle circulaire uniforme ne suffit plus à expliquer les dégradations. Lien avec ta thèse : justification bibliographique centrale de ta problématique. | AP2: De Beer & Fisher (2013) ; De Beer et al. (2004) | AQ2: Non | AR2: =IF($B2="","",IFERROR(INDEX(Paramètres!$Q$6:$Q$13,MATCH($G2,Paramètres!$P$6:$P$13,0)),"")) -> Mesure de la pression de contact pneu-chaussée | AS2: =IF($B2="","",IFERROR(INDEX(Paramètres!$T$6:$T$11,MATCH($I2,Paramètres!$S$6:$S$11,0)),"")) -> octobre 2026 | AT2: =IF($B2="","",IFERROR(INDEX(Paramètres!$C$27:$C$29,MATCH($H2,Paramètres!$B$27:$B$29,0)),0)) -> 6 | AW2: =IF($B2="","",$B2&".md") -> debeer2012toward.md | AX2: =IF($B2="","",COUNTIF($I$2:I2,$I2)) -> 1 | AY2: =IF($B2="","",$I2&"-"&$AX2) -> 1-1 | AZ2: https://scholar.google.com/scholar?q=%22Toward+using+tire-road+contact+stresses+in+pavement+design+and+analysis%22 | BA2: =IF($B2="","",$M2+(1000-ROW())/100000) -> 140.00998 | BB2: BIB-001_DeBeer-etal_2012_Tire-road-contact-stresses-pavement-design.pdf
A3: BIB-002 | B3: debeer2013sim | C3: =IF($B3="","",IFERROR(LEFT(LEFT($V3,FIND(";",$V3&";")-1),FIND(",",LEFT($V3,FIND(";",$V3&";")-1))-1),LEFT($V3,FIND(";",$V3&";")-1))&IF((LEN($V3)-LEN(SUBSTITUTE($V3,";",""))+1)=1,"",IF((LEN($V3)-LEN(SUBSTITUTE($V3,";",""))+1)=2," & "&IFERROR(LEFT(TRIM(MID($V3,FIND(";",$V3)+1,FIND(";",$V3&";",FIND(";",$V3)+1)-FIND(";",$V3)-1)),FIND(",",TRIM(MID($V3,FIND(";",$V3)+1,FIND(";",$V3&";",FIND(";",$V3)+1)-FIND(";",$V3)-1)))-1),TRIM(MID($V3,FIND(";",$V3)+1,FIND(";",$V3&";",FIND(";",$V3)+1)-FIND(";",$V3)-1)))," et al."))&" ("&$W3&")") -> De Beer & Fisher (2013) | D3: Stress-In-Motion (SIM) system for capturing tri-axial tyre–road interaction in the contact patch | E3: =IF(OR($B3="",$AF3=""),"",HYPERLINK(IF(AND(Paramètres!$C$13<>"",$AJ3="Éditeur (abonnement)"),Paramètres!$C$13&$AF3,$AF3),"Ouvrir : "&$AE3)) -> Ouvrir : Page éditeur (DOI) | F3: Non | G3: 1 | H3: INCONTOURNABLE | I3: 1 | J3: À lire | K3: =IF($B3="","",IF($J3="Lu","Lu",IF($J3="Écarté","Écarté",IF($I3<Paramètres!$C$8,"EN RETARD",IF($I3=Paramètres!$C$8,"Ce mois-ci",IF($I3=Paramètres!$C$8+1,"Mois prochain","À venir")))))) -> Ce mois-ci | L3: =IF($B3="","",IF($AL3="Non vérifié","Ne pas citer en l'état : métadonnées non vérifiées",IF($AL3="Partiel","Vérification à compléter avant de citer",IF($O3="Oui","",IF(OR($AJ3="PDF libre",$AJ3="PDF libre (dépôt)"),"PDF libre à télécharger",IF($AJ3="Éditeur (abonnement)","À télécharger via l'accès ENTPE",IF($AJ3="Payant (boutique)","À consulter via l'abonnement de l'école",IF($AJ3="Non diffusé (à demander)","Document à demander (feuille Demandes)","Texte intégral à localiser")))))))) | M3: =IF($B3="","",IF(OR($J3="Lu",$J3="Écarté"),0,IFERROR(INDEX(Paramètres!$C$17:$C$19,MATCH($H3,Paramètres!$B$17:$B$19,0)),0)+Paramètres!$C$20*(7-$I3)+IF($I3<Paramètres!$C$8,Paramètres!$C$21,0)+IF($F3="Oui",Paramètres!$C$22,0)+IF($AL3<>"Vérifié",Paramètres!$C$23,0)+IF(AND($O3<>"Oui",OR($AJ3="PDF libre",$AJ3="PDF libre (dépôt)")),Paramètres!$C$24,0))) -> 130 | O3: =IF($BB3="","Non",HYPERLINK(DossierPDF&$BB3,"Oui")) -> Oui | P3: Non | Q3: Non | T3: JOUR | U3: =IF($B3="","",IFERROR(INDEX(Paramètres!$N$6:$N$13,MATCH($T3,Paramètres!$M$6:$M$13,0)),$T3)) -> Article de revue | V3: De Beer, M.; Fisher, C. | W3: 2013 | X3: Measurement | Y3: 46 | Z3: 7 | AA3: 2155-2173 | AC3: 10.1016/j.measurement.2013.03.012 | AE3: Page éditeur (DOI) | AF3: https://doi.org/10.1016/j.measurement.2013.03.012 | AG3: =IF($AC3="","",HYPERLINK("https://doi.org/"&$AC3,"doi.org")) -> doi.org | AH3: =IF($AZ3="","",HYPERLINK($AZ3,"Scholar")) -> Scholar | AI3: Payant | AJ3: Éditeur (abonnement) | AK3: Elsevier (ScienceDirect) : accès par l'abonnement de l'ENTPE. | AL3: Vérifié | AM3: OpenAlex (DOI) | AN3: 22/09/2026 | AO3: Description complète du système SIM : conception des capteurs, étalonnage, capture des trois composantes de contrainte dans l'empreinte. Lien avec ta thèse : pour discuter la fiabilité des données que tu as utilisées et préparer une campagne de mesure dédiée (ta perspective n° 1). | AP3: De Beer et al. (1997) | AQ3: Non | AR3: =IF($B3="","",IFERROR(INDEX(Paramètres!$Q$6:$Q$13,MATCH($G3,Paramètres!$P$6:$P$13,0)),"")) -> Mesure de la pression de contact pneu-chaussée | AS3: =IF($B3="","",IFERROR(INDEX(Paramètres!$T$6:$T$11,MATCH($I3,Paramètres!$S$6:$S$11,0)),"")) -> octobre 2026 | AT3: =IF($B3="","",IFERROR(INDEX(Paramètres!$C$27:$C$29,MATCH($H3,Paramètres!$B$27:$B$29,0)),0)) -> 6 | AW3: =IF($B3="","",$B3&".md") -> debeer2013sim.md | AX3: =IF($B3="","",COUNTIF($I$2:I3,$I3)) -> 2 | AY3: =IF($B3="","",$I3&"-"&$AX3) -> 1-2 | AZ3: https://scholar.google.com/scholar?q=%22Stress-In-Motion+%28SIM%29+system+for+capturing+tri-axial+tyre%E2%80%93road+interaction+in+the+contact+patch%22 | BA3: =IF($B3="","",$M3+(1000-ROW())/100000) -> 130.00997 | BB3: BIB-002_DeBeer-Fisher_2013_Stress-In-Motion-SIM-system.pdf
A4: BIB-003 | B4: tielking1989afesc | C4: =IF($B4="","",IFERROR(LEFT(LEFT($V4,FIND(";",$V4&";")-1),FIND(",",LEFT($V4,FIND(";",$V4&";")-1))-1),LEFT($V4,FIND(";",$V4&";")-1))&IF((LEN($V4)-LEN(SUBSTITUTE($V4,";",""))+1)=1,"",IF((LEN($V4)-LEN(SUBSTITUTE($V4,";",""))+1)=2," & "&IFERROR(LEFT(TRIM(MID($V4,FIND(";",$V4)+1,FIND(";",$V4&";",FIND(";",$V4)+1)-FIND(";",$V4)-1)),FIND(",",TRIM(MID($V4,FIND(";",$V4)+1,FIND(";",$V4&";",FIND(";",$V4)+1)-FIND(";",$V4)-1)))-1),TRIM(MID($V4,FIND(";",$V4)+1,FIND(";",$V4&";",FIND(";",$V4)+1)-FIND(";",$V4)-1)))," et al."))&" ("&$W4&")") -> Tielking (1989) | D4: Aircraft tire/pavement pressure distribution | E4: =IF(OR($B4="",$AF4=""),"",HYPERLINK(IF(AND(Paramètres!$C$13<>"",$AJ4="Éditeur (abonnement)"),Paramètres!$C$13&$AF4,$AF4),"Ouvrir : "&$AE4)) -> Ouvrir : Texte intégral libre | F4: Non | G4: 1 | H4: INCONTOURNABLE | I4: 1 | J4: À lire | K4: =IF($B4="","",IF($J4="Lu","Lu",IF($J4="Écarté","Écarté",IF($I4<Paramètres!$C$8,"EN RETARD",IF($I4=Paramètres!$C$8,"Ce mois-ci",IF($I4=Paramètres!$C$8+1,"Mois prochain","À venir")))))) -> Ce mois-ci | L4: =IF($B4="","",IF($AL4="Non vérifié","Ne pas citer en l'état : métadonnées non vérifiées",IF($AL4="Partiel","Vérification à compléter avant de citer",IF($O4="Oui","",IF(OR($AJ4="PDF libre",$AJ4="PDF libre (dépôt)"),"PDF libre à télécharger",IF($AJ4="Éditeur (abonnement)","À télécharger via l'accès ENTPE",IF($AJ4="Payant (boutique)","À consulter via l'abonnement de l'école",IF($AJ4="Non diffusé (à demander)","Document à demander (feuille Demandes)","Texte intégral à localiser")))))))) | M4: =IF($B4="","",IF(OR($J4="Lu",$J4="Écarté"),0,IFERROR(INDEX(Paramètres!$C$17:$C$19,MATCH($H4,Paramètres!$B$17:$B$19,0)),0)+Paramètres!$C$20*(7-$I4)+IF($I4<Paramètres!$C$8,Paramètres!$C$21,0)+IF($F4="Oui",Paramètres!$C$22,0)+IF($AL4<>"Vérifié",Paramètres!$C$23,0)+IF(AND($O4<>"Oui",OR($AJ4="PDF libre",$AJ4="PDF libre (dépôt)")),Paramètres!$C$24,0))) -> 130 | O4: =IF($BB4="","Non",HYPERLINK(DossierPDF&$BB4,"Oui")) -> Oui | P4: Non | Q4: Non | T4: RPRT | U4: =IF($B4="","",IFERROR(INDEX(Paramètres!$N$6:$N$13,MATCH($T4,Paramètres!$M$6:$M$13,0)),$T4)) -> Rapport | V4: Tielking, J. T. | W4: 1989 | AB4: Air Force Engineering & Services Center, Tyndall AFB (Texas Transportation Institute, Texas A&M University) | AD4: ESL-TR-89-01 ; DTIC ADA279100 ; 53 p. | AE4: Texte intégral libre | AF4: https://apps.dtic.mil/sti/pdfs/ADA279100.pdf | AG4: =IF($AC4="","",HYPERLINK("https://doi.org/"&$AC4,"doi.org")) | AH4: =IF($AZ4="","",HYPERLINK($AZ4,"Scholar")) -> Scholar | AI4: Libre | AJ4: PDF libre | AK4: PDF public sur DTIC (diffusion libre). | AL4: Vérifié | AM4: Page de documentation du rapport (DTIC) | AN4: 22/09/2026 | AO4: Pressions de contact pneu-chaussée calculées pour sept pneus d'avion différents, dans un rapport pour l'US Air Force. Lien avec ta thèse : une des rares sources publiques sur la distribution sous pneu d'avion ; point de comparaison pour ta transposition du pneu de camion au pneu d'avion. | AP4: Tielking (1989) ; Airbus S.A.S. (2010) | AQ4: Oui | AR4: =IF($B4="","",IFERROR(INDEX(Paramètres!$Q$6:$Q$13,MATCH($G4,Paramètres!$P$6:$P$13,0)),"")) -> Mesure de la pression de contact pneu-chaussée | AS4: =IF($B4="","",IFERROR(INDEX(Paramètres!$T$6:$T$11,MATCH($I4,Paramètres!$S$6:$S$11,0)),"")) -> octobre 2026 | AT4: =IF($B4="","",IFERROR(INDEX(Paramètres!$C$27:$C$29,MATCH($H4,Paramètres!$B$27:$B$29,0)),0)) -> 6 | AW4: =IF($B4="","",$B4&".md") -> tielking1989afesc.md | AX4: =IF($B4="","",COUNTIF($I$2:I4,$I4)) -> 3 | AY4: =IF($B4="","",$I4&"-"&$AX4) -> 1-3 | AZ4: https://scholar.google.com/scholar?q=%22Aircraft+tire%2Fpavement+pressure+distribution%22 | BA4: =IF($B4="","",$M4+(1000-ROW())/100000) -> 130.00996 | BB4: BIB-003_Tielking_1989_Aircraft-tire-pavement-pressure-distribution.pdf
A5: BIB-004 | B5: sadoun2022topdown | C5: =IF($B5="","",IFERROR(LEFT(LEFT($V5,FIND(";",$V5&";")-1),FIND(",",LEFT($V5,FIND(";",$V5&";")-1))-1),LEFT($V5,FIND(";",$V5&";")-1))&IF((LEN($V5)-LEN(SUBSTITUTE($V5,";",""))+1)=1,"",IF((LEN($V5)-LEN(SUBSTITUTE($V5,";",""))+1)=2," & "&IFERROR(LEFT(TRIM(MID($V5,FIND(";",$V5)+1,FIND(";",$V5&";",FIND(";",$V5)+1)-FIND(";",$V5)-1)),FIND(",",TRIM(MID($V5,FIND(";",$V5)+1,FIND(";",$V5&";",FIND(";",$V5)+1)-FIND(";",$V5)-1)))-1),TRIM(MID($V5,FIND(";",$V5)+1,FIND(";",$V5&";",FIND(";",$V5)+1)-FIND(";",$V5)-1)))," et al."))&" ("&$W5&")") -> Sadoun et al. (2022) | D5: Top-down cracking in airfield pavement structures—An in-situ test survey | E5: =IF(OR($B5="",$AF5=""),"",HYPERLINK(IF(AND(Paramètres!$C$13<>"",$AJ5="Éditeur (abonnement)"),Paramètres!$C$13&$AF5,$AF5),"Ouvrir : "&$AE5)) -> Ouvrir : Page éditeur (DOI) | F5: Oui | G5: 6 | H5: INCONTOURNABLE | I5: 1 | J5: À lire | K5: =IF($B5="","",IF($J5="Lu","Lu",IF($J5="Écarté","Écarté",IF($I5<Paramètres!$C$8,"EN RETARD",IF($I5=Paramètres!$C$8,"Ce mois-ci",IF($I5=Paramètres!$C$8+1,"Mois prochain","À venir")))))) -> Ce mois-ci | L5: =IF($B5="","",IF($AL5="Non vérifié","Ne pas citer en l'état : métadonnées non vérifiées",IF($AL5="Partiel","Vérification à compléter avant de citer",IF($O5="Oui","",IF(OR($AJ5="PDF libre",$AJ5="PDF libre (dépôt)"),"PDF libre à télécharger",IF($AJ5="Éditeur (abonnement)","À télécharger via l'accès ENTPE",IF($AJ5="Payant (boutique)","À consulter via l'abonnement de l'école",IF($AJ5="Non diffusé (à demander)","Document à demander (feuille Demandes)","Texte intégral à localiser")))))))) | M5: =IF($B5="","",IF(OR($J5="Lu",$J5="Écarté"),0,IFERROR(INDEX(Paramètres!$C$17:$C$19,MATCH($H5,Paramètres!$B$17:$B$19,0)),0)+Paramètres!$C$20*(7-$I5)+IF($I5<Paramètres!$C$8,Paramètres!$C$21,0)+IF($F5="Oui",Paramètres!$C$22,0)+IF($AL5<>"Vérifié",Paramètres!$C$23,0)+IF(AND($O5<>"Oui",OR($AJ5="PDF libre",$AJ5="PDF libre (dépôt)")),Paramètres!$C$24,0))) -> 140 | O5: =IF($BB5="","Non",HYPERLINK(DossierPDF&$BB5,"Oui")) -> Oui | P5: Non | Q5: Non | T5: CONF | U5: =IF($B5="","",IFERROR(INDEX(Paramètres!$N$6:$N$13,MATCH($T5,Paramètres!$M$6:$M$13,0)),$T5)) -> Communication (actes) | V5: Sadoun, A.; Broutin, M.; Boulkhemair, I.; Duprey, A.; Mazars, A.; Huault, M. | W5: 2022 | X5: Proceedings of the RILEM International Symposium on Bituminous Materials (ISBM Lyon 2020) | Y5: 27 | AA5: 1861-1867 | AB5: Springer | AC5: 10.1007/978-3-030-46455-4_236 | AD5: RILEM Bookseries, vol. 27 | AE5: Page éditeur (DOI) | AF5: https://doi.org/10.1007/978-3-030-46455-4_236 | AG5: =IF($AC5="","",HYPERLINK("https://doi.org/"&$AC5,"doi.org")) -> doi.org | AH5: =IF($AZ5="","",HYPERLINK($AZ5,"Scholar")) -> Scholar | AI5: Payant | AJ5: Éditeur (abonnement) | AK5: SpringerLink : abonnement ENTPE ; sinon demander le texte à M. Broutin (co-auteur). | AL5: Vérifié | AM5: OpenAlex (DOI) ; chapitre mis en ligne en 2021, volume daté 2022 | AN5: 22/09/2026 | AO5: Fissuration descendante observée sur des chaussées aéronautiques françaises ; expérimentation sur la piste 14R-32L de Toulouse-Blagnac, chaussée rigide renforcée par une couche bitumineuse (aéroport, Cerema, Airbus, STAC) : ovalisation, inclinomètres, déplacements des dalles sous A319, essais HWD, modèle éléments finis 2D avec enrobés viscoélastiques. Lien avec ta thèse : c'est l'observation de terrain de ton TFE (Fig. 1-27) qui justifie un critère de surface ; la structure étant composite, la comparaison avec ta chaussée souple reste qualitative. | AP5: Canestrari & Ingrassia (2020) ; Wang & Al-Qadi (2010) ; Cardoso da Silva et al. (2025) | AQ5: Oui | AR5: =IF($B5="","",IFERROR(INDEX(Paramètres!$Q$6:$Q$13,MATCH($G5,Paramètres!$P$6:$P$13,0)),"")) -> Fatigue et endommagement | AS5: =IF($B5="","",IFERROR(INDEX(Paramètres!$T$6:$T$11,MATCH($I5,Paramètres!$S$6:$S$11,0)),"")) -> octobre 2026 | AT5: =IF($B5="","",IFERROR(INDEX(Paramètres!$C$27:$C$29,MATCH($H5,Paramètres!$B$27:$B$29,0)),0)) -> 6 | AW5: =IF($B5="","",$B5&".md") -> sadoun2022topdown.md | AX5: =IF($B5="","",COUNTIF($I$2:I5,$I5)) -> 4 | AY5: =IF($B5="","",$I5&"-"&$AX5) -> 1-4 | AZ5: https://scholar.google.com/scholar?q=%22Top-down+cracking+in+airfield+pavement+structures%E2%80%94An+in-situ+test+survey%22 | BA5: =IF($B5="","",$M5+(1000-ROW())/100000) -> 140.00995 | BB5: BIB-004_Sadoun-etal_2022_Top-down-cracking-airfield-pavements.pdf
A6: BIB-005 | B6: airbus2010htpt | C6: =IF($B6="","",IFERROR(LEFT(LEFT($V6,FIND(";",$V6&";")-1),FIND(",",LEFT($V6,FIND(";",$V6&";")-1))-1),LEFT($V6,FIND(";",$V6&";")-1))&IF((LEN($V6)-LEN(SUBSTITUTE($V6,";",""))+1)=1,"",IF((LEN($V6)-LEN(SUBSTITUTE($V6,";",""))+1)=2," & "&IFERROR(LEFT(TRIM(MID($V6,FIND(";",$V6)+1,FIND(";",$V6&";",FIND(";",$V6)+1)-FIND(";",$V6)-1)),FIND(",",TRIM(MID($V6,FIND(";",$V6)+1,FIND(";",$V6&";",FIND(";",$V6)+1)-FIND(";",$V6)-1)))-1),TRIM(MID($V6,FIND(";",$V6)+1,FIND(";",$V6&";",FIND(";",$V6)+1)-FIND(";",$V6)-1)))," et al."))&" ("&$W6&")") -> Airbus S.A.S. (2010) | D6: High Tire Pressure Test (HTPT) — Final report | E6: =IF(OR($B6="",$AF6=""),"",HYPERLINK(IF(AND(Paramètres!$C$13<>"",$AJ6="Éditeur (abonnement)"),Paramètres!$C$13&$AF6,$AF6),"Ouvrir : "&$AE6)) -> Ouvrir : Texte intégral libre | F6: Oui | G6: 7 | H6: INCONTOURNABLE | I6: 1 | J6: À lire | K6: =IF($B6="","",IF($J6="Lu","Lu",IF($J6="Écarté","Écarté",IF($I6<Paramètres!$C$8,"EN RETARD",IF($I6=Paramètres!$C$8,"Ce mois-ci",IF($I6=Paramètres!$C$8+1,"Mois prochain","À venir")))))) -> Ce mois-ci | L6: =IF($B6="","",IF($AL6="Non vérifié","Ne pas citer en l'état : métadonnées non vérifiées",IF($AL6="Partiel","Vérification à compléter avant de citer",IF($O6="Oui","",IF(OR($AJ6="PDF libre",$AJ6="PDF libre (dépôt)"),"PDF libre à télécharger",IF($AJ6="Éditeur (abonnement)","À télécharger via l'accès ENTPE",IF($AJ6="Payant (boutique)","À consulter via l'abonnement de l'école",IF($AJ6="Non diffusé (à demander)","Document à demander (feuille Demandes)","Texte intégral à localiser")))))))) | M6: =IF($B6="","",IF(OR($J6="Lu",$J6="Écarté"),0,IFERROR(INDEX(Paramètres!$C$17:$C$19,MATCH($H6,Paramètres!$B$17:$B$19,0)),0)+Paramètres!$C$20*(7-$I6)+IF($I6<Paramètres!$C$8,Paramètres!$C$21,0)+IF($F6="Oui",Paramètres!$C$22,0)+IF($AL6<>"Vérifié",Paramètres!$C$23,0)+IF(AND($O6<>"Oui",OR($AJ6="PDF libre",$AJ6="PDF libre (dépôt)")),Paramètres!$C$24,0))) -> 140 | O6: =IF($BB6="","Non",HYPERLINK(DossierPDF&$BB6,"Oui")) -> Oui | P6: Non | Q6: Non | T6: RPRT | U6: =IF($B6="","",IFERROR(INDEX(Paramètres!$N$6:$N$13,MATCH($T6,Paramètres!$M$6:$M$13,0)),$T6)) -> Rapport | V6: Airbus S.A.S. | W6: 2010 | AB6: Airbus S.A.S., Airport Operations | AD6: X32RP0926801, Issue 2.0 | AE6: Texte intégral libre | AF6: https://www.aircraft.airbus.com/sites/g/files/jlcbta126/files/2023-02/Airbus-Commercial-Aircraft-HTPT-final-report-31-Aug-2010.pdf | AG6: =IF($AC6="","",HYPERLINK("https://doi.org/"&$AC6,"doi.org")) | AH6: =IF($AZ6="","",HYPERLINK($AZ6,"Scholar")) -> Scholar | AI6: Libre | AJ6: PDF libre | AK6: Rapport public sur le site d'Airbus. | AL6: Vérifié | AM6: PDF Airbus (page de titre, §3.4.2, Fig. 26) | AN6: 22/09/2026 | AO6: Rapport final de l'essai HTPT mené par Airbus avec le STAC, le LCPC, le LRPC de Toulouse, Michelin et Vancouver2 : chaussées souples en vraie grandeur à 15 et 17,5 bars, avec une partie consacrée à la mécanique du pneu (cartes de pression calculées pour le 1400x530R23 à 32 % de déflexion, §3.4.2, p. 44-50). Lien avec ta thèse : source de la déflexion de 32 % et des cartes sur lesquelles tu lis un rapport Pmax/Pgonflage de 1,7 à 2,1 (valeur non écrite dans les pages lues). Document public ; ta Fig. 1-23 montre des pressions calculées, non mesurées. | AP6: STAC (2011) ; Tielking (1989) | AQ6: Oui | AR6: =IF($B6="","",IFERROR(INDEX(Paramètres!$Q$6:$Q$13,MATCH($G6,Paramètres!$P$6:$P$13,0)),"")) -> Chaussées aéronautiques | AS6: =IF($B6="","",IFERROR(INDEX(Paramètres!$T$6:$T$11,MATCH($I6,Paramètres!$S$6:$S$11,0)),"")) -> octobre 2026 | AT6: =IF($B6="","",IFERROR(INDEX(Paramètres!$C$27:$C$29,MATCH($H6,Paramètres!$B$27:$B$29,0)),0)) -> 6 | AW6: =IF($B6="","",$B6&".md") -> airbus2010htpt.md | AX6: =IF($B6="","",COUNTIF($I$2:I6,$I6)) -> 5 | AY6: =IF($B6="","",$I6&"-"&$AX6) -> 1-5 | AZ6: https://scholar.google.com/scholar?q=%22High+Tire+Pressure+Test+%28HTPT%29+%E2%80%94+Final+report%22 | BA6: =IF($B6="","",$M6+(1000-ROW())/100000) -> 140.00994 | BB6: BIB-005_Airbus_2010_HTPT-final-report.pdf
A7: BIB-006 | B7: petitjean2001pep | C7: =IF($B7="","",IFERROR(LEFT(LEFT($V7,FIND(";",$V7&";")-1),FIND(",",LEFT($V7,FIND(";",$V7&";")-1))-1),LEFT($V7,FIND(";",$V7&";")-1))&IF((LEN($V7)-LEN(SUBSTITUTE($V7,";",""))+1)=1,"",IF((LEN($V7)-LEN(SUBSTITUTE($V7,";",""))+1)=2," & "&IFERROR(LEFT(TRIM(MID($V7,FIND(";",$V7)+1,FIND(";",$V7&";",FIND(";",$V7)+1)-FIND(";",$V7)-1)),FIND(",",TRIM(MID($V7,FIND(";",$V7)+1,FIND(";",$V7&";",FIND(";",$V7)+1)-FIND(";",$V7)-1)))-1),TRIM(MID($V7,FIND(";",$V7)+1,FIND(";",$V7&";",FIND(";",$V7)+1)-FIND(";",$V7)-1)))," et al."))&" ("&$W7&")") -> Petitjean et al. (2001) | D7: LCPC / Airbus / STBA A380 Pavement Experimental Programme | E7: =IF(OR($B7="",$AF7=""),"",HYPERLINK(IF(AND(Paramètres!$C$13<>"",$AJ7="Éditeur (abonnement)"),Paramètres!$C$13&$AF7,$AF7),"Ouvrir : "&$AE7)) -> Ouvrir : Texte intégral libre | F7: Oui | G7: 7 | H7: INCONTOURNABLE | I7: 1 | J7: À lire | K7: =IF($B7="","",IF($J7="Lu","Lu",IF($J7="Écarté","Écarté",IF($I7<Paramètres!$C$8,"EN RETARD",IF($I7=Paramètres!$C$8,"Ce mois-ci",IF($I7=Paramètres!$C$8+1,"Mois prochain","À venir")))))) -> Ce mois-ci | L7: =IF($B7="","",IF($AL7="Non vérifié","Ne pas citer en l'état : métadonnées non vérifiées",IF($AL7="Partiel","Vérification à compléter avant de citer",IF($O7="Oui","",IF(OR($AJ7="PDF libre",$AJ7="PDF libre (dépôt)"),"PDF libre à télécharger",IF($AJ7="Éditeur (abonnement)","À télécharger via l'accès ENTPE",IF($AJ7="Payant (boutique)","À consulter via l'abonnement de l'école",IF($AJ7="Non diffusé (à demander)","Document à demander (feuille Demandes)","Texte intégral à localiser")))))))) | M7: =IF($B7="","",IF(OR($J7="Lu",$J7="Écarté"),0,IFERROR(INDEX(Paramètres!$C$17:$C$19,MATCH($H7,Paramètres!$B$17:$B$19,0)),0)+Paramètres!$C$20*(7-$I7)+IF($I7<Paramètres!$C$8,Paramètres!$C$21,0)+IF($F7="Oui",Paramètres!$C$22,0)+IF($AL7<>"Vérifié",Paramètres!$C$23,0)+IF(AND($O7<>"Oui",OR($AJ7="PDF libre",$AJ7="PDF libre (dépôt)")),Paramètres!$C$24,0))) -> 140 | O7: =IF($BB7="","Non",HYPERLINK(DossierPDF&$BB7,"Oui")) -> Oui | P7: Non | Q7: Non | T7: RPRT | U7: =IF($B7="","",IFERROR(INDEX(Paramètres!$N$6:$N$13,MATCH($T7,Paramètres!$M$6:$M$13,0)),$T7)) -> Rapport | V7: Petitjean, J.; Fabre, C.; Martin, J.; Bezavada, V.; Piau, J.-M.; Balay, J.; Albin, A.; Albin, C. | W7: 2001 | AB7: Airbus Industrie / LCPC / STBA / Aéroports de Paris | AD7: Rapport d'étude STBA, 173 p. | AE7: Texte intégral libre | AF7: https://www.stac.aviation-civile.gouv.fr/sites/default/files/rapportPEP.pdf | AG7: =IF($AC7="","",HYPERLINK("https://doi.org/"&$AC7,"doi.org")) | AH7: =IF($AZ7="","",HYPERLINK($AZ7,"Scholar")) -> Scholar | AI7: Libre | AJ7: PDF libre | AK7: PDF public sur le site du STAC (aussi diffusé par Airbus). | AL7: Vérifié | AM7: Page STAC + page d'auteurs du PDF | AN7: 22/09/2026 | AO7: Programme expérimental A380 sur chaussées souples instrumentées à Toulouse sous simulateur de train d'atterrissage. Lien avec ta thèse : données de validation de ta simulation (déformations en base de couche bitumineuse) et source des modules des couches. | AP7: Airbus S.A.S. (2010) | AQ7: Oui | AR7: =IF($B7="","",IFERROR(INDEX(Paramètres!$Q$6:$Q$13,MATCH($G7,Paramètres!$P$6:$P$13,0)),"")) -> Chaussées aéronautiques | AS7: =IF($B7="","",IFERROR(INDEX(Paramètres!$T$6:$T$11,MATCH($I7,Paramètres!$S$6:$S$11,0)),"")) -> octobre 2026 | AT7: =IF($B7="","",IFERROR(INDEX(Paramètres!$C$27:$C$29,MATCH($H7,Paramètres!$B$27:$B$29,0)),0)) -> 6 | AW7: =IF($B7="","",$B7&".md") -> petitjean2001pep.md | AX7: =IF($B7="","",COUNTIF($I$2:I7,$I7)) -> 6 | AY7: =IF($B7="","",$I7&"-"&$AX7) -> 1-6 | AZ7: https://scholar.google.com/scholar?q=%22LCPC+%2F+Airbus+%2F+STBA+A380+Pavement+Experimental+Programme%22 | BA7: =IF($B7="","",$M7+(1000-ROW())/100000) -> 140.00993 | BB7: BIB-006_Petitjean-etal_2001_A380-pavement-experimental-programme.pdf
A8: BIB-007 | B8: stac2011htpt | C8: =IF($B8="","",IFERROR(LEFT(LEFT($V8,FIND(";",$V8&";")-1),FIND(",",LEFT($V8,FIND(";",$V8&";")-1))-1),LEFT($V8,FIND(";",$V8&";")-1))&IF((LEN($V8)-LEN(SUBSTITUTE($V8,";",""))+1)=1,"",IF((LEN($V8)-LEN(SUBSTITUTE($V8,";",""))+1)=2," & "&IFERROR(LEFT(TRIM(MID($V8,FIND(";",$V8)+1,FIND(";",$V8&";",FIND(";",$V8)+1)-FIND(";",$V8)-1)),FIND(",",TRIM(MID($V8,FIND(";",$V8)+1,FIND(";",$V8&";",FIND(";",$V8)+1)-FIND(";",$V8)-1)))-1),TRIM(MID($V8,FIND(";",$V8)+1,FIND(";",$V8&";",FIND(";",$V8)+1)-FIND(";",$V8)-1)))," et al."))&" ("&$W8&")") -> STAC (2011) | D8: High tire pressure test — Rapport d'étude (version 1) | E8: =IF(OR($B8="",$AF8=""),"",HYPERLINK(IF(AND(Paramètres!$C$13<>"",$AJ8="Éditeur (abonnement)"),Paramètres!$C$13&$AF8,$AF8),"Ouvrir : "&$AE8)) -> Ouvrir : Texte intégral libre | F8: Non | G8: 7 | H8: INCONTOURNABLE | I8: 1 | J8: À lire | K8: =IF($B8="","",IF($J8="Lu","Lu",IF($J8="Écarté","Écarté",IF($I8<Paramètres!$C$8,"EN RETARD",IF($I8=Paramètres!$C$8,"Ce mois-ci",IF($I8=Paramètres!$C$8+1,"Mois prochain","À venir")))))) -> Ce mois-ci | L8: =IF($B8="","",IF($AL8="Non vérifié","Ne pas citer en l'état : métadonnées non vérifiées",IF($AL8="Partiel","Vérification à compléter avant de citer",IF($O8="Oui","",IF(OR($AJ8="PDF libre",$AJ8="PDF libre (dépôt)"),"PDF libre à télécharger",IF($AJ8="Éditeur (abonnement)","À télécharger via l'accès ENTPE",IF($AJ8="Payant (boutique)","À consulter via l'abonnement de l'école",IF($AJ8="Non diffusé (à demander)","Document à demander (feuille Demandes)","Texte intégral à localiser")))))))) | M8: =IF($B8="","",IF(OR($J8="Lu",$J8="Écarté"),0,IFERROR(INDEX(Paramètres!$C$17:$C$19,MATCH($H8,Paramètres!$B$17:$B$19,0)),0)+Paramètres!$C$20*(7-$I8)+IF($I8<Paramètres!$C$8,Paramètres!$C$21,0)+IF($F8="Oui",Paramètres!$C$22,0)+IF($AL8<>"Vérifié",Paramètres!$C$23,0)+IF(AND($O8<>"Oui",OR($AJ8="PDF libre",$AJ8="PDF libre (dépôt)")),Paramètres!$C$24,0))) -> 130 | O8: =IF($BB8="","Non",HYPERLINK(DossierPDF&$BB8,"Oui")) -> Oui | P8: Non | Q8: Non | T8: RPRT | U8: =IF($B8="","",IFERROR(INDEX(Paramètres!$N$6:$N$13,MATCH($T8,Paramètres!$M$6:$M$13,0)),$T8)) -> Rapport | V8: STAC | W8: 2011 | AB8: DGAC, Service technique de l'Aviation civile | AD8: Rapport d'étude STAC, 120 p. | AE8: Texte intégral libre | AF8: https://www.stac.aviation-civile.gouv.fr/en/publications/high-tire-pressure-test | AG8: =IF($AC8="","",HYPERLINK("https://doi.org/"&$AC8,"doi.org")) | AH8: =IF($AZ8="","",HYPERLINK($AZ8,"Scholar")) -> Scholar | AI8: Libre | AJ8: PDF libre | AK8: Lecture en ligne gratuite depuis la page du STAC (liseuse Calaméo). | AL8: Vérifié | AM8: Page de publication du STAC | AN8: 22/09/2026 | AO8: Version STAC de la campagne HTPT à Toulouse-Blagnac : sept sections souples, pressions de 15 et 17,5 bars, charges de 28,7 et 33,2 t par roue, mesures de déformations et d'orniérage. Lien avec ta thèse : complément public du rapport Airbus, côté partenaire ; une version 2 était annoncée. | AP8: Airbus S.A.S. (2010) | AQ8: Oui | AR8: =IF($B8="","",IFERROR(INDEX(Paramètres!$Q$6:$Q$13,MATCH($G8,Paramètres!$P$6:$P$13,0)),"")) -> Chaussées aéronautiques | AS8: =IF($B8="","",IFERROR(INDEX(Paramètres!$T$6:$T$11,MATCH($I8,Paramètres!$S$6:$S$11,0)),"")) -> octobre 2026 | AT8: =IF($B8="","",IFERROR(INDEX(Paramètres!$C$27:$C$29,MATCH($H8,Paramètres!$B$27:$B$29,0)),0)) -> 6 | AW8: =IF($B8="","",$B8&".md") -> stac2011htpt.md | AX8: =IF($B8="","",COUNTIF($I$2:I8,$I8)) -> 7 | AY8: =IF($B8="","",$I8&"-"&$AX8) -> 1-7 | AZ8: https://scholar.google.com/scholar?q=%22High+tire+pressure+test+%E2%80%94+Rapport+d%27%C3%A9tude+%28version+1%29%22 | BA8: =IF($B8="","",$M8+(1000-ROW())/100000) -> 130.00992 | BB8: BIB-007_STAC_2011_High-tire-pressure-test-rapport-etude.pdf
